2025-04-01 21:21:28,892:DEBUG:certbot._internal.main:certbot version: 3.3.0
2025-04-01 21:21:28,893:DEBUG:certbot._internal.main:Location of certbot entry point: /usr/local/bin/certbot
2025-04-01 21:21:28,893:DEBUG:certbot._internal.main:Arguments: ['--webroot', '-w', '/var/www/certbot', '-d', 'abeta.app']
2025-04-01 21:21:28,893:DEBUG:certbot._internal.main:Discovered plugins: PluginsRegistry(PluginEntryPoint#manual,PluginEntryPoint#null,PluginEntryPoint#standalone,PluginEntryPoint#webroot)
2025-04-01 21:21:28,916:DEBUG:certbot._internal.log:Root logging level set at 30
2025-04-01 21:21:28,918:DEBUG:certbot._internal.plugins.selection:Requested authenticator webroot and installer None
2025-04-01 21:21:28,918:DEBUG:certbot._internal.plugins.selection:Single candidate plugin: * webroot
Description: Saves the necessary validation files to a .well-known/acme-challenge/ directory within the nominated webroot path. A separate HTTP server must be running and serving files from the webroot path. HTTP challenge only (wildcards not supported).
Interfaces: Authenticator, Plugin
Entry point: EntryPoint(name='webroot', value='certbot._internal.plugins.webroot:Authenticator', group='certbot.plugins')
Initialized: <certbot._internal.plugins.webroot.Authenticator object at 0x7bba0070bc80>
Prep: True
2025-04-01 21:21:28,919:DEBUG:certbot._internal.plugins.selection:Selected authenticator <certbot._internal.plugins.webroot.Authenticator object at 0x7bba0070bc80> and installer None
2025-04-01 21:21:28,919:INFO:certbot._internal.plugins.selection:Plugins selected: Authenticator webroot, Installer None
2025-04-01 21:21:28,919:WARNING:certbot._internal.display.obj:Skipped user interaction because Certbot doesn't appear to be running in a terminal. You should probably include --non-interactive or --force-interactive on the command line.
2025-04-01 21:21:28,919:DEBUG:certbot._internal.display.obj:Falling back to default  for the prompt:
Enter email address or hit Enter to skip.

2025-04-01 21:21:28,982:DEBUG:acme.client:Sending GET request to https://acme-v02.api.letsencrypt.org/directory.
2025-04-01 21:21:28,985:DEBUG:urllib3.connectionpool:Starting new HTTPS connection (1): acme-v02.api.letsencrypt.org:443
2025-04-01 21:21:29,524:DEBUG:urllib3.connectionpool:https://acme-v02.api.letsencrypt.org:443 "GET /directory HTTP/1.1" 200 1042
2025-04-01 21:21:29,524:DEBUG:acme.client:Received response:
HTTP 200
Server: nginx
Date: Tue, 01 Apr 2025 21:21:29 GMT
Content-Type: application/json
Content-Length: 1042
Connection: keep-alive
Cache-Control: public, max-age=0, no-cache
X-Frame-Options: DENY
Strict-Transport-Security: max-age=604800

{
  "Alz8mQZnd4I": "https://community.letsencrypt.org/t/adding-random-entries-to-the-directory/33417",
  "keyChange": "https://acme-v02.api.letsencrypt.org/acme/key-change",
  "meta": {
    "caaIdentities": [
      "letsencrypt.org"
    ],
    "profiles": {
      "classic": "https://letsencrypt.org/docs/profiles#classic",
      "shortlived": "https://letsencrypt.org/docs/profiles#shortlived (not yet generally available)",
      "tlsserver": "https://letsencrypt.org/docs/profiles#tlsserver (not yet generally available)"
    },
    "termsOfService": "https://letsencrypt.org/documents/LE-SA-v1.5-February-24-2025.pdf",
    "website": "https://letsencrypt.org"
  },
  "newAccount": "https://acme-v02.api.letsencrypt.org/acme/new-acct",
  "newNonce": "https://acme-v02.api.letsencrypt.org/acme/new-nonce",
  "newOrder": "https://acme-v02.api.letsencrypt.org/acme/new-order",
  "renewalInfo": "https://acme-v02.api.letsencrypt.org/draft-ietf-acme-ari-03/renewalInfo",
  "revokeCert": "https://acme-v02.api.letsencrypt.org/acme/revoke-cert"
}
2025-04-01 21:21:29,526:DEBUG:certbot._internal.log:Exiting abnormally:
Traceback (most recent call last):
  File "/usr/local/bin/certbot", line 33, in <module>
    sys.exit(load_entry_point('certbot', 'console_scripts', 'certbot')())
             ^^^^^^^^^^^^^^^^^^^^^^^^^^^^^^^^^^^^^^^^^^^^^^^^^^^^^^^^^^^
  File "/opt/certbot/src/certbot/certbot/main.py", line 19, in main
    return internal_main.main(cli_args)
           ^^^^^^^^^^^^^^^^^^^^^^^^^^^^
  File "/opt/certbot/src/certbot/certbot/_internal/main.py", line 1871, in main
    return config.func(config, plugins)
           ^^^^^^^^^^^^^^^^^^^^^^^^^^^^
  File "/opt/certbot/src/certbot/certbot/_internal/main.py", line 1559, in certonly
    le_client = _init_le_client(config, auth, installer)
                ^^^^^^^^^^^^^^^^^^^^^^^^^^^^^^^^^^^^^^^^
  File "/opt/certbot/src/certbot/certbot/_internal/main.py", line 831, in _init_le_client
    acc, acme = _determine_account(config)
                ^^^^^^^^^^^^^^^^^^^^^^^^^^
  File "/opt/certbot/src/certbot/certbot/_internal/main.py", line 739, in _determine_account
    acc, acme = client.register(
                ^^^^^^^^^^^^^^^^
  File "/opt/certbot/src/certbot/certbot/_internal/client.py", line 204, in register
    regr = perform_registration(acme, config, tos_cb)
           ^^^^^^^^^^^^^^^^^^^^^^^^^^^^^^^^^^^^^^^^^^
  File "/opt/certbot/src/certbot/certbot/_internal/client.py", line 247, in perform_registration
    tos_cb(tos)
  File "/opt/certbot/src/certbot/certbot/_internal/main.py", line 715, in _tos_cb
    result = display_util.yesno(msg, cli_flag="--agree-tos", force_interactive=True)
             ^^^^^^^^^^^^^^^^^^^^^^^^^^^^^^^^^^^^^^^^^^^^^^^^^^^^^^^^^^^^^^^^^^^^^^^
  File "/opt/certbot/src/certbot/certbot/display/util.py", line 124, in yesno
    return obj.get_display().yesno(message, yes_label=yes_label, no_label=no_label, default=default,
           ^^^^^^^^^^^^^^^^^^^^^^^^^^^^^^^^^^^^^^^^^^^^^^^^^^^^^^^^^^^^^^^^^^^^^^^^^^^^^^^^^^^^^^^^^
  File "/opt/certbot/src/certbot/certbot/_internal/display/obj.py", line 189, in yesno
    ans = util.input_with_timeout("{yes}/{no}: ".format(
          ^^^^^^^^^^^^^^^^^^^^^^^^^^^^^^^^^^^^^^^^^^^^^^
  File "/opt/certbot/src/certbot/certbot/_internal/display/util.py", line 68, in input_with_timeout
    raise EOFError
EOFError
2025-04-01 21:21:29,533:ERROR:certbot._internal.log:An unexpected error occurred:
2025-04-01 21:21:29,533:ERROR:certbot._internal.log:EOFError
